## 1. 概述

在本教程中，我们将讨论Kotlin中的异常处理。

## 2. 异常

异常是在程序执行过程中出现并破坏常规流程的问题，这可能由于各种原因而发生，例如无效的算术运算，对空对象的引用。

**异常处理是优雅地处理此类问题并继续执行程序的技术**。

## 3. Kotlin异常

在Kotlin中，只有程序运行时抛出的[非受检的异常](https://www.baeldung.com/java-checked-unchecked-exceptions#unchecked)，所有异常类都源自Throwable类。**Kotlin使用throw关键字来抛出异常对象**。

Kotlin虽然继承了Java的异常概念，但是不像Java那样支持[受检异常](https://www.baeldung.com/java-checked-unchecked-exceptions#checked)。

受检异常被认为是Java中一个有争议的特性，**它会降低开发人员的工作效率，同时又不会额外提高代码质量**。除其他问题外，受检的异常还会导致样板代码、使用lambda表达式时的困难。

因此，与许多其他现代编程语言一样，Kotlin开发人员也决定不将受检异常作为一种语言特性包含在内。

## 4. Try-Catch块

我们可以使用try-catch块在Kotlin中进行异常处理，**特别是，可以抛出异常的代码放在try块中**。此外，相应的catch块用于处理异常。

**事实上，try块之后总是跟着一个catch或finally块，或两者兼而有之**。

让我们看一下try-catch块：

```kotlin
try {
    val message = "Welcome toKotlinTutorials"
    message.toInt()
} catch (exception: NumberFormatException) {
    // ...
}
```

### 4.1 Try-Catch块作为表达式

表达式可以是一个或多个值、变量、运算符和函数的组合，这些值、变量、运算符和函数执行以提供另一个值。**因此，我们可以将try-catch块用作Kotlin中的表达式**。

此外，try-catch表达式的返回值是try或catch块的最后一个表达式。如果发生异常，则返回catch块的值。但是，表达式的结果不受finally块的影响。

以下是我们如何将try-catch用作表达式：

```kotlin
val number = try {
    val message = "Welcome toKotlinTutorials"
    message.toInt()
} catch (exception: NumberFormatException) {
    // ...
}
return number
```

### 4.2 多个catch块

**我们可以将多个catch块与Kotlin中的try块一起使用**，特别是，如果我们在try块中执行不同类型的操作，这通常是必需的，这增加了捕获多个异常的可能性。

**此外，我们必须对所有的catch块进行排序，从最具体的异常到最一般的异常**。例如，ArithmeticException的catch块必须在Exception的catch块之前。

让我们看一下使用多个catch块的方法：

```kotlin
try {
    val result = 25 / 0
    result
} catch (exception: NumberFormatException) {
    // ...
} catch (exception: ArithmeticException) {
    // ...
} catch (exception: Exception) {
    // ...
}
```

### 4.3 嵌套的Try-Catch块

**我们可以使用嵌套的try-catch块，在另一个try块中实现一个try-catch块**。例如，当一个代码块可能抛出异常并且在该代码块内，另一个语句可能另外抛出异常时，可能需要这样做。

让我们看看如何使用嵌套的try-catch块：

```kotlin
try {
    val firstNumber = 50 / 2 * 0
    try {
        val secondNumber = 100 / firstNumber
        secondNumber
    } catch (exception: ArithmeticException) {
        // ...
    }
} catch (exception: NumberFormatException) {
    // ...
}
```

## 5. finally块

**我们可以使用finally块来始终执行代码，无论是否处理异常**。此外，我们可以通过省略catch块来将finally块与try块一起使用。

让我们看一下finally块：

```kotlin
try {
    val message = "Welcome toKotlinTutorials"
    message.toInt()
} catch (exception: NumberFormatException) {
    // ...
} finally {
    // ...
}
```

## 6. throw关键字

**我们可以在Kotlin中使用throw关键字来抛出某个异常或者自定义异常**。

以下是我们如何在Kotlin中使用throw关键字：

```kotlin
val message = "Welcome toKotlinTutorials"
if (message.length > 10) throw IllegalArgumentException("String is invalid")
else return message.length
```

**我们也可以使用throw作为Kotlin中的表达式**。例如，它可以用作Elvis表达式的一部分：

```kotlin
val message: String? = null
return message?.length ?: throw IllegalArgumentException("String is null")
```

**throw表达式返回一个Nothing类型的值**，这种特殊类型没有值，用于指示无法访问的代码块。另外，我们也可以在函数中使用Nothing类型来表示它将始终抛出异常：

```kotlin
fun abstractException(message: String): Nothing {
    throw RuntimeException(message)
}
```

## 7. @Throws注解

**我们可以使用@Throws注解来提供Kotlin和Java之间的互操作性**，由于Kotlin没有受检的异常，因此它不会声明抛出的异常。让我们在Kotlin中定义一个函数：

```kotlin
fun readFile(): String? {
    val filePath = null
    return filePath ?: throw IOException("File path is invalid")
}
```

现在我们可以从Java调用Kotlin函数并捕获异常，下面是我们如何用Java编写try-catch：

```java
try {
    readFile();
}
catch (IOException e) {
    // ...
}
```

Java编译器将显示一条错误消息，因为Kotlin函数没有声明异常。在这种情况下，我们可以使用Kotlin中的@Throws注解来处理错误：

```kotlin
@Throws(IOException::class)
fun readFile(): String? {
    val filePath = null
    return filePath ?: throw IOException("File path is invalid")
}
```

## 8. 总结

在本教程中，我们讨论了Kotlin中异常处理的各种方式。